[0m05:09:20.489725 [debug] [MainThread]: Sending event: {'category': 'dbt', 'action': 'invocation', 'label': 'start', 'context': [<snowplow_tracker.self_describing_json.SelfDescribingJson object at 0x00000207391B3A10>, <snowplow_tracker.self_describing_json.SelfDescribingJson object at 0x0000020737225BD0>, <snowplow_tracker.self_describing_json.SelfDescribingJson object at 0x000002073A593C50>]}


============================== 05:09:20.507367 | 385f691a-fb60-49bd-90c1-2083a180a5f1 ==============================
[0m05:09:20.507367 [info ] [MainThread]: Running with dbt=1.10.4
[0m05:09:20.507937 [debug] [MainThread]: running dbt with arguments {'printer_width': '80', 'indirect_selection': 'eager', 'log_cache_events': 'False', 'write_json': 'True', 'partial_parse': 'True', 'cache_selected_only': 'False', 'warn_error': 'None', 'version_check': 'True', 'profiles_dir': 'C:\\Users\\sachi\\.dbt', 'log_path': 'logs', 'fail_fast': 'False', 'debug': 'False', 'use_colors': 'True', 'use_experimental_parser': 'False', 'empty': 'None', 'quiet': 'False', 'no_print': 'None', 'log_format': 'default', 'invocation_command': 'dbt init', 'warn_error_options': 'WarnErrorOptionsV2(error=[], warn=[], silence=[])', 'static_parser': 'True', 'target_path': 'None', 'introspect': 'True', 'send_anonymous_usage_stats': 'True'}
[0m05:09:20.517173 [info ] [MainThread]: Creating dbt configuration folder at C:\Users\sachi\.dbt
[0m05:09:47.946440 [debug] [MainThread]: Starter project path: C:\Users\sachi\AppData\Local\Programs\Python\Python313\Lib\site-packages\dbt\include\starter_project
[0m05:09:47.961620 [info ] [MainThread]: 
Your new dbt project "custom_postgres" was created!

For more information on how to configure the profiles.yml file,
please consult the dbt documentation here:

  https://docs.getdbt.com/docs/configure-your-profile

One more thing:

Need help? Don't hesitate to reach out to us via GitHub issues or on Slack:

  https://community.getdbt.com/

Happy modeling!

[0m05:09:47.961957 [info ] [MainThread]: Setting up your profile.
[0m05:14:29.294652 [error] [MainThread]: Encountered an error:

[0m05:14:29.296659 [error] [MainThread]: Traceback (most recent call last):
  File "C:\Users\sachi\AppData\Local\Programs\Python\Python313\Lib\site-packages\dbt\cli\requires.py", line 161, in wrapper
    result, success = func(*args, **kwargs)
                      ~~~~^^^^^^^^^^^^^^^^^
  File "C:\Users\sachi\AppData\Local\Programs\Python\Python313\Lib\site-packages\dbt\cli\requires.py", line 111, in wrapper
    return func(*args, **kwargs)
  File "C:\Users\sachi\AppData\Local\Programs\Python\Python313\Lib\site-packages\dbt\cli\main.py", line 483, in init
    results = task.run()
  File "C:\Users\sachi\AppData\Local\Programs\Python\Python313\Lib\site-packages\dbt\task\init.py", line 346, in run
    self.setup_profile(profile_name)
    ~~~~~~~~~~~~~~~~~~^^^^^^^^^^^^^^
  File "C:\Users\sachi\AppData\Local\Programs\Python\Python313\Lib\site-packages\dbt\task\init.py", line 262, in setup_profile
    self.create_profile_from_target(adapter, profile_name=profile_name)
    ~~~~~~~~~~~~~~~~~~~~~~~~~~~~~~~^^^^^^^^^^^^^^^^^^^^^^^^^^^^^^^^^^^^
  File "C:\Users\sachi\AppData\Local\Programs\Python\Python313\Lib\site-packages\dbt\task\init.py", line 179, in create_profile_from_target
    self.create_profile_from_profile_template(profile_template, profile_name)
    ~~~~~~~~~~~~~~~~~~~~~~~~~~~~~~~~~~~~~~~~~^^^^^^^^^^^^^^^^^^^^^^^^^^^^^^^^
  File "C:\Users\sachi\AppData\Local\Programs\Python\Python313\Lib\site-packages\dbt\task\init.py", line 163, in create_profile_from_profile_template
    target = self.generate_target_from_input(prompts, initial_target)
  File "C:\Users\sachi\AppData\Local\Programs\Python\Python313\Lib\site-packages\dbt\task\init.py", line 129, in generate_target_from_input
    target[key] = click.prompt(
                  ~~~~~~~~~~~~^
        text, default=default, hide_input=hide_input, type=type
        ^^^^^^^^^^^^^^^^^^^^^^^^^^^^^^^^^^^^^^^^^^^^^^^^^^^^^^^
    )
    ^
  File "C:\Users\sachi\AppData\Local\Programs\Python\Python313\Lib\site-packages\click\termui.py", line 168, in prompt
    value = prompt_func(prompt)
  File "C:\Users\sachi\AppData\Local\Programs\Python\Python313\Lib\site-packages\click\termui.py", line 151, in prompt_func
    raise Abort() from None
click.exceptions.Abort

[0m05:14:29.297483 [debug] [MainThread]: Command `dbt init` failed at 05:14:29.297404 after 308.92 seconds
[0m05:14:29.297707 [debug] [MainThread]: Sending event: {'category': 'dbt', 'action': 'invocation', 'label': 'end', 'context': [<snowplow_tracker.self_describing_json.SelfDescribingJson object at 0x000002073A612C40>, <snowplow_tracker.self_describing_json.SelfDescribingJson object at 0x000002073B716210>, <snowplow_tracker.self_describing_json.SelfDescribingJson object at 0x000002073A647680>]}
[0m05:14:29.297936 [debug] [MainThread]: Flushing usage events
[0m05:14:30.354607 [debug] [MainThread]: An error was encountered while trying to flush usage events
[0m05:14:37.568825 [debug] [MainThread]: Sending event: {'category': 'dbt', 'action': 'invocation', 'label': 'start', 'context': [<snowplow_tracker.self_describing_json.SelfDescribingJson object at 0x000001BDEB71FA10>, <snowplow_tracker.self_describing_json.SelfDescribingJson object at 0x000001BDE9785BD0>, <snowplow_tracker.self_describing_json.SelfDescribingJson object at 0x000001BDECB03C50>]}


============================== 05:14:37.571747 | c510f2d5-01d5-4183-a8d8-5b0eb63e69b3 ==============================
[0m05:14:37.571747 [info ] [MainThread]: Running with dbt=1.10.4
[0m05:14:37.572170 [debug] [MainThread]: running dbt with arguments {'printer_width': '80', 'indirect_selection': 'eager', 'write_json': 'True', 'log_cache_events': 'False', 'partial_parse': 'True', 'cache_selected_only': 'False', 'profiles_dir': 'C:\\Users\\sachi\\.dbt', 'version_check': 'True', 'debug': 'False', 'log_path': 'logs', 'warn_error': 'None', 'fail_fast': 'False', 'use_colors': 'True', 'use_experimental_parser': 'False', 'no_print': 'None', 'quiet': 'False', 'empty': 'None', 'warn_error_options': 'WarnErrorOptionsV2(error=[], warn=[], silence=[])', 'invocation_command': 'dbt init', 'log_format': 'default', 'introspect': 'True', 'target_path': 'None', 'static_parser': 'True', 'send_anonymous_usage_stats': 'True'}
[0m05:14:50.919758 [info ] [MainThread]: A project called custom_postgres already exists here.
[0m05:14:50.920430 [debug] [MainThread]: Command `dbt init` succeeded at 05:14:50.920342 after 13.46 seconds
[0m05:14:50.920656 [debug] [MainThread]: Sending event: {'category': 'dbt', 'action': 'invocation', 'label': 'end', 'context': [<snowplow_tracker.self_describing_json.SelfDescribingJson object at 0x000001BDEDB88640>, <snowplow_tracker.self_describing_json.SelfDescribingJson object at 0x000001BDEDB6A7B0>, <snowplow_tracker.self_describing_json.SelfDescribingJson object at 0x000001BDEC93B9B0>]}
[0m05:14:50.920886 [debug] [MainThread]: Flushing usage events
[0m05:14:51.932089 [debug] [MainThread]: An error was encountered while trying to flush usage events
[0m05:15:02.900209 [debug] [MainThread]: Sending event: {'category': 'dbt', 'action': 'invocation', 'label': 'start', 'context': [<snowplow_tracker.self_describing_json.SelfDescribingJson object at 0x00000287E9853A10>, <snowplow_tracker.self_describing_json.SelfDescribingJson object at 0x00000287E7881BD0>, <snowplow_tracker.self_describing_json.SelfDescribingJson object at 0x00000287EAC33C50>]}


============================== 05:15:02.902995 | 55fd7b84-60e9-4784-bc0b-7e11d28832c5 ==============================
[0m05:15:02.902995 [info ] [MainThread]: Running with dbt=1.10.4
[0m05:15:02.903398 [debug] [MainThread]: running dbt with arguments {'printer_width': '80', 'indirect_selection': 'eager', 'log_cache_events': 'False', 'write_json': 'True', 'partial_parse': 'True', 'cache_selected_only': 'False', 'profiles_dir': 'C:\\Users\\sachi\\.dbt', 'version_check': 'True', 'warn_error': 'None', 'log_path': 'logs', 'fail_fast': 'False', 'debug': 'False', 'use_colors': 'True', 'use_experimental_parser': 'False', 'empty': 'None', 'quiet': 'False', 'no_print': 'None', 'log_format': 'default', 'static_parser': 'True', 'introspect': 'True', 'invocation_command': 'dbt init', 'target_path': 'None', 'warn_error_options': 'WarnErrorOptionsV2(error=[], warn=[], silence=[])', 'send_anonymous_usage_stats': 'True'}
[0m05:15:10.060580 [debug] [MainThread]: Starter project path: C:\Users\sachi\AppData\Local\Programs\Python\Python313\Lib\site-packages\dbt\include\starter_project
[0m05:15:10.067685 [info ] [MainThread]: 
Your new dbt project "custom_postgres" was created!

For more information on how to configure the profiles.yml file,
please consult the dbt documentation here:

  https://docs.getdbt.com/docs/configure-your-profile

One more thing:

Need help? Don't hesitate to reach out to us via GitHub issues or on Slack:

  https://community.getdbt.com/

Happy modeling!

[0m05:15:10.067966 [info ] [MainThread]: Setting up your profile.
[0m05:17:33.384679 [info ] [MainThread]: Profile custom_postgres written to C:\Users\sachi\.dbt\profiles.yml using target's profile_template.yml and your supplied values. Run 'dbt debug' to validate the connection.
[0m05:17:33.385375 [debug] [MainThread]: Command `dbt init` succeeded at 05:17:33.385294 after 150.56 seconds
[0m05:17:33.385608 [debug] [MainThread]: Sending event: {'category': 'dbt', 'action': 'invocation', 'label': 'end', 'context': [<snowplow_tracker.self_describing_json.SelfDescribingJson object at 0x00000287EBCBAC40>, <snowplow_tracker.self_describing_json.SelfDescribingJson object at 0x00000287EBC9A8D0>, <snowplow_tracker.self_describing_json.SelfDescribingJson object at 0x00000287EAA6B9B0>]}
[0m05:17:33.385837 [debug] [MainThread]: Flushing usage events
[0m05:17:34.367122 [debug] [MainThread]: An error was encountered while trying to flush usage events
